<mujoco>
  <extension>
    <plugin plugin="mujoco.sdf.torus">
      <instance name="torus">
        <config key="radius1" value="1.5"/>
        <config key="radius2" value="0.10"/>
      </instance>
    </plugin>
  </extension>

  <asset>
    <mesh name="torus">
      <plugin instance="torus"/>
    </mesh>
    <texture name="grid" type="2d" builtin="checker" rgb1=".1 .2 .3" rgb2=".2 .3 .4" width="300" height="300"/>
    <material name="grid" texture="grid" texrepeat="8 8" reflectance=".2"/>
  </asset>

  <option sdf_iterations="10" sdf_initpoints="40"/>

  <default>
    <geom solref="0.01 1" solimp=".95 .99 .0001" friction="0.8"/>
  </default>

  <worldbody>
    <camera name="my_camera" pos="-5 -5 10" euler="30 -20 10"/>
    
    <geom name="floor" size="10 10 10" type="plane" material="grid"/>
    <body name="wheel_and_axle" pos="0 0 1.6">
      <freejoint/>
      <geom type="sdf" mesh="torus" rgba=".2 .2 .8 1" mass="100" euler = "10 90 90">
        <plugin instance="torus"/>
      </geom>
      <geom name="cylinder" type="cylinder" size="0.1 1" euler="0 90 0" mass="1" pos="0 0 0"/>
      <body name="sphere" pos="0 0 0">
        <joint name="slider1" type="slide" axis="1 0 0" range="-1 1"/>
        <geom type="sphere" size="0.2" rgba="0 0 1 1" mass="10"/>
      </body>
      <camera name="track" pos="0 -6 3" xyaxes="1 0 0 0 1 2" mode="track"/>
    </body>
    
    <light name="left" pos="-2 0 7" cutoff="80"/>
    <light name="right" pos="2 0 7" cutoff="80"/>
    
  </worldbody>
  
  <actuator>
    <motor name="my_motor" joint="slider1"/>
  </actuator>

  <keyframe>
    <key name="spinning" qpos="0 0 1.9 0 0 0 0 0" qvel="0 0 0 0 0 0 5"/>
  </keyframe>
</mujoco>