{\rtf1\ansi\ansicpg1252\cocoartf2709
\cocoatextscaling0\cocoaplatform0{\fonttbl\f0\fnil\fcharset0 Menlo-Regular;}
{\colortbl;\red255\green255\blue255;\red194\green126\blue101;\red23\green23\blue23;\red202\green202\blue202;
}
{\*\expandedcolortbl;;\cssrgb\c80784\c56863\c47059;\cssrgb\c11765\c11765\c11765;\cssrgb\c83137\c83137\c83137;
}
\margl1440\margr1440\vieww34000\viewh20240\viewkind0
\deftab720
\pard\pardeftab720\partightenfactor0

\f0\fs24 \cf2 \cb3 \expnd0\expndtw0\kerning0
\outl0\strokewidth0 \strokec2 <mujoco>\cf4 \cb1 \strokec4 \
\cf2 \cb3 \strokec2   <extension>\cf4 \cb1 \strokec4 \
\cf2 \cb3 \strokec2     <plugin plugin="mujoco.sdf.torus">\cf4 \cb1 \strokec4 \
\cf2 \cb3 \strokec2       <instance name="torus">\cf4 \cb1 \strokec4 \
\cf2 \cb3 \strokec2         <config key="radius1" value="0.90"/>\cf4 \cb1 \strokec4 \
\cf2 \cb3 \strokec2         <config key="radius2" value="0.1"/>\cf4 \cb1 \strokec4 \
\cf2 \cb3 \strokec2       </instance>\cf4 \cb1 \strokec4 \
\cf2 \cb3 \strokec2     </plugin>\cf4 \cb1 \strokec4 \
\cf2 \cb3 \strokec2   </extension>\cf4 \cb1 \strokec4 \
\
\cf2 \cb3 \strokec2   <asset>\cf4 \cb1 \strokec4 \
\cf2 \cb3 \strokec2     <mesh name="torus">\cf4 \cb1 \strokec4 \
\cf2 \cb3 \strokec2       <plugin instance="torus"/>\cf4 \cb1 \strokec4 \
\cf2 \cb3 \strokec2     </mesh>\cf4 \cb1 \strokec4 \
\cf2 \cb3 \strokec2     <texture name="grid" type="2d" builtin="checker" rgb1=".1 .2 .3" rgb2=".2 .3 .4" width="300" height="300"/>\cf4 \cb1 \strokec4 \
\cf2 \cb3 \strokec2     <material name="grid" texture="grid" texrepeat="80 80" reflectance=".2"/>\cf4 \cb1 \strokec4 \
\cf2 \cb3 \strokec2     <texture name="torus_texture" type="2d" file="/Users/adampearl/Desktop/cyr-wheel/Control/green_texture.png"/>\cf4 \cb1 \strokec4 \
\cf2 \cb3 \strokec2     <material name="torus_material" texture="torus_texture" texrepeat="1 1" reflectance=".5"/>\cf4 \cb1 \strokec4 \
\cf2 \cb3 \strokec2   \cf4 \cb1 \strokec4 \
\cf2 \cb3 \strokec2   </asset>\cf4 \cb1 \strokec4 \
\
\cf2 \cb3 \strokec2   <option sdf_iterations="10" sdf_initpoints="40" gravity="0 0 -1"/>\cf4 \cb1 \strokec4 \
\
\cf2 \cb3 \strokec2   <default>\cf4 \cb1 \strokec4 \
\cf2 \cb3 \strokec2     <geom solref="0.01 1" solimp="1 1 0" friction = "0.8"/>\cf4 \cb1 \strokec4 \
\cf2 \cb3 \strokec2   </default>\cf4 \cb1 \strokec4 \
\
\cf2 \cb3 \strokec2   <worldbody>\cf4 \cb1 \strokec4 \
\cf2 \cb3 \strokec2     <camera name="my_camera" pos="-5 -5 10" euler="30 -20 10"/>\cf4 \cb1 \strokec4 \
\
\cf2 \cb3 \strokec2     <geom name="floor" size="100 100 100" type="plane" material="grid" friction = \'931 0 0"/>\cf4 \cb1 \strokec4 \
\cf2 \cb3 \strokec2     <body name="wheel_and_axle" pos="0 0 1.6">\cf4 \cb1 \strokec4 \
\cf2 \cb3 \strokec2       <freejoint/>\cf4 \cb1 \strokec4 \
\cf2 \cb3 \strokec2       <geom type="sdf" mesh="torus"  material = "torus_material" mass="1" euler = "0 90 0" friction = "1 0 0">\cf4 \cb1 \strokec4 \
\cf2 \cb3 \strokec2         <plugin instance="torus"/>\cf4 \cb1 \strokec4 \
\cf2 \cb3 \strokec2       </geom>\cf4 \cb1 \strokec4 \
\cf2 \cb3 \strokec2       <geom name="cylinder" type="cylinder" size="0.05 1" euler="0 90 0" mass="0" pos="0 0 0" friction = \'930 0 0"/>\cf4 \cb1 \strokec4 \
\cf2 \cb3 \strokec2       <body name="sphere" pos="0 0 0">\cf4 \cb1 \strokec4 \
\cf2 \cb3 \strokec2         <joint name="slider1" type="slide" axis="1 0 0" range="-1 1"/>\cf4 \cb1 \strokec4 \
\cf2 \cb3 \strokec2         <geom type="sphere" size="0.2" rgba="0 0 1 1" mass="0.2" friction="0 0 0"/>\cf4 \cb1 \strokec4 \
\cf2 \cb3 \strokec2       </body>\cf4 \cb1 \strokec4 \
\cf2 \cb3 \strokec2       <camera name="track" pos="0 -6 3" xyaxes="1 0 0 0 1 2" mode="track"/>\cf4 \cb1 \strokec4 \
\cf2 \cb3 \strokec2       <camera name="sideview" pos="-2 0 1" xyaxes="0 -1 0 1 0 2" mode="track"/>\cf4 \cb1 \strokec4 \
\cf2 \cb3 \strokec2     </body>\cf4 \cb1 \strokec4 \
\
\cf2 \cb3 \strokec2     <light name="left" pos="-2 0 7" cutoff="80"/>\cf4 \cb1 \strokec4 \
\cf2 \cb3 \strokec2     <light name="right" pos="2 0 7" cutoff="80"/>\cf4 \cb1 \strokec4 \
\
\cf2 \cb3 \strokec2   </worldbody>\cf4 \cb1 \strokec4 \
\
\cf2 \cb3 \strokec2   <actuator>\cf4 \cb1 \strokec4 \
\cf2 \cb3 \strokec2     <motor name="my_motor" joint="slider1"/>\cf4 \cb1 \strokec4 \
\cf2 \cb3 \strokec2   </actuator>\cf4 \cb1 \strokec4 \
\cf2 \cb3 \strokec2   <keyframe>\cf4 \cb1 \strokec4 \
\cf2 \cb3 \strokec2     <key name="spinning" qpos="0 0 1 0 0 0 0 0" qvel="0 -1 0 1 0 0 0.5\'94/>\cf4 \cb1 \strokec4 \
\cf2 \cb3 \strokec2   </keyframe>\cf4 \cb1 \strokec4 \
\cf2 \cb3 \strokec2 </mujoco>\cf4 \cb1 \strokec4 \
}